{
 "cells": [
  {
   "cell_type": "markdown",
   "id": "bb361450",
   "metadata": {},
   "source": [
    "## BUSINESS UNDERSTANDING"
   ]
  },
  {
   "cell_type": "code",
   "execution_count": 9,
   "id": "d14b0d7e",
   "metadata": {},
   "outputs": [
    {
     "name": "stdout",
     "output_type": "stream",
     "text": [
      "Requirement already satisfied: pandas in c:\\users\\user\\anaconda3\\lib\\site-packages (2.3.0)\n",
      "Requirement already satisfied: numpy in c:\\users\\user\\anaconda3\\lib\\site-packages (2.0.2)\n",
      "Requirement already satisfied: pytz>=2020.1 in c:\\users\\user\\anaconda3\\lib\\site-packages (from pandas) (2022.1)\n",
      "Requirement already satisfied: python-dateutil>=2.8.2 in c:\\users\\user\\anaconda3\\lib\\site-packages (from pandas) (2.8.2)\n",
      "Requirement already satisfied: tzdata>=2022.7 in c:\\users\\user\\anaconda3\\lib\\site-packages (from pandas) (2025.2)\n",
      "Requirement already satisfied: six>=1.5 in c:\\users\\user\\anaconda3\\lib\\site-packages (from python-dateutil>=2.8.2->pandas) (1.16.0)\n"
     ]
    },
    {
     "name": "stderr",
     "output_type": "stream",
     "text": [
      "WARNING: Retrying (Retry(total=4, connect=None, read=None, redirect=None, status=None)) after connection broken by 'NewConnectionError('<pip._vendor.urllib3.connection.HTTPSConnection object at 0x000001D220B6DF40>: Failed to establish a new connection: [Errno 11001] getaddrinfo failed')': /simple/pandas/\n",
      "WARNING: Retrying (Retry(total=3, connect=None, read=None, redirect=None, status=None)) after connection broken by 'NewConnectionError('<pip._vendor.urllib3.connection.HTTPSConnection object at 0x000001D220B9D2B0>: Failed to establish a new connection: [Errno 11001] getaddrinfo failed')': /simple/pandas/\n",
      "WARNING: Retrying (Retry(total=2, connect=None, read=None, redirect=None, status=None)) after connection broken by 'NewConnectionError('<pip._vendor.urllib3.connection.HTTPSConnection object at 0x000001D220B9D460>: Failed to establish a new connection: [Errno 11001] getaddrinfo failed')': /simple/pandas/\n",
      "WARNING: Retrying (Retry(total=1, connect=None, read=None, redirect=None, status=None)) after connection broken by 'NewConnectionError('<pip._vendor.urllib3.connection.HTTPSConnection object at 0x000001D220B9D610>: Failed to establish a new connection: [Errno 11001] getaddrinfo failed')': /simple/pandas/\n",
      "WARNING: Retrying (Retry(total=0, connect=None, read=None, redirect=None, status=None)) after connection broken by 'NewConnectionError('<pip._vendor.urllib3.connection.HTTPSConnection object at 0x000001D220B9D7C0>: Failed to establish a new connection: [Errno 11001] getaddrinfo failed')': /simple/pandas/\n",
      "WARNING: Retrying (Retry(total=4, connect=None, read=None, redirect=None, status=None)) after connection broken by 'NewConnectionError('<pip._vendor.urllib3.connection.HTTPSConnection object at 0x000001D220BAE4C0>: Failed to establish a new connection: [Errno 11001] getaddrinfo failed')': /simple/numpy/\n",
      "WARNING: Retrying (Retry(total=3, connect=None, read=None, redirect=None, status=None)) after connection broken by 'NewConnectionError('<pip._vendor.urllib3.connection.HTTPSConnection object at 0x000001D220BAE760>: Failed to establish a new connection: [Errno 11001] getaddrinfo failed')': /simple/numpy/\n",
      "WARNING: Retrying (Retry(total=2, connect=None, read=None, redirect=None, status=None)) after connection broken by 'NewConnectionError('<pip._vendor.urllib3.connection.HTTPSConnection object at 0x000001D220BAE910>: Failed to establish a new connection: [Errno 11001] getaddrinfo failed')': /simple/numpy/\n",
      "WARNING: Retrying (Retry(total=1, connect=None, read=None, redirect=None, status=None)) after connection broken by 'NewConnectionError('<pip._vendor.urllib3.connection.HTTPSConnection object at 0x000001D220BAEAC0>: Failed to establish a new connection: [Errno 11001] getaddrinfo failed')': /simple/numpy/\n",
      "WARNING: Retrying (Retry(total=0, connect=None, read=None, redirect=None, status=None)) after connection broken by 'NewConnectionError('<pip._vendor.urllib3.connection.HTTPSConnection object at 0x000001D220BAEC70>: Failed to establish a new connection: [Errno 11001] getaddrinfo failed')': /simple/numpy/\n"
     ]
    }
   ],
   "source": [
    "!pip install --upgrade pandas numpy"
   ]
  },
  {
   "cell_type": "code",
   "execution_count": 11,
   "id": "e51e7aa3",
   "metadata": {},
   "outputs": [
    {
     "ename": "ValueError",
     "evalue": "numpy.dtype size changed, may indicate binary incompatibility. Expected 96 from C header, got 88 from PyObject",
     "output_type": "error",
     "traceback": [
      "\u001b[1;31m---------------------------------------------------------------------------\u001b[0m",
      "\u001b[1;31mValueError\u001b[0m                                Traceback (most recent call last)",
      "\u001b[1;32m~\\AppData\\Local\\Temp\\ipykernel_35404\\2551288385.py\u001b[0m in \u001b[0;36m<module>\u001b[1;34m\u001b[0m\n\u001b[0;32m      1\u001b[0m \u001b[1;32mimport\u001b[0m \u001b[0mzipfile\u001b[0m\u001b[1;33m\u001b[0m\u001b[1;33m\u001b[0m\u001b[0m\n\u001b[0;32m      2\u001b[0m \u001b[1;32mimport\u001b[0m \u001b[0mos\u001b[0m\u001b[1;33m\u001b[0m\u001b[1;33m\u001b[0m\u001b[0m\n\u001b[1;32m----> 3\u001b[1;33m \u001b[1;32mimport\u001b[0m \u001b[0mpandas\u001b[0m \u001b[1;32mas\u001b[0m \u001b[0mpd\u001b[0m\u001b[1;33m\u001b[0m\u001b[1;33m\u001b[0m\u001b[0m\n\u001b[0m\u001b[0;32m      4\u001b[0m \u001b[1;33m\u001b[0m\u001b[0m\n\u001b[0;32m      5\u001b[0m \u001b[1;31m# Load Data set\u001b[0m\u001b[1;33m\u001b[0m\u001b[1;33m\u001b[0m\u001b[0m\n",
      "\u001b[1;32m~\\anaconda3\\lib\\site-packages\\pandas\\__init__.py\u001b[0m in \u001b[0;36m<module>\u001b[1;34m\u001b[0m\n\u001b[0;32m     78\u001b[0m \u001b[1;32mimport\u001b[0m \u001b[0mpandas\u001b[0m\u001b[1;33m.\u001b[0m\u001b[0mcore\u001b[0m\u001b[1;33m.\u001b[0m\u001b[0mconfig_init\u001b[0m  \u001b[1;31m# pyright: ignore[reportUnusedImport] # noqa: F401\u001b[0m\u001b[1;33m\u001b[0m\u001b[1;33m\u001b[0m\u001b[0m\n\u001b[0;32m     79\u001b[0m \u001b[1;33m\u001b[0m\u001b[0m\n\u001b[1;32m---> 80\u001b[1;33m from pandas.core.api import (\n\u001b[0m\u001b[0;32m     81\u001b[0m     \u001b[1;31m# dtype\u001b[0m\u001b[1;33m\u001b[0m\u001b[1;33m\u001b[0m\u001b[0m\n\u001b[0;32m     82\u001b[0m     \u001b[0mArrowDtype\u001b[0m\u001b[1;33m,\u001b[0m\u001b[1;33m\u001b[0m\u001b[1;33m\u001b[0m\u001b[0m\n",
      "\u001b[1;32m~\\anaconda3\\lib\\site-packages\\pandas\\core\\api.py\u001b[0m in \u001b[0;36m<module>\u001b[1;34m\u001b[0m\n\u001b[1;32m----> 1\u001b[1;33m from pandas._libs import (\n\u001b[0m\u001b[0;32m      2\u001b[0m     \u001b[0mNaT\u001b[0m\u001b[1;33m,\u001b[0m\u001b[1;33m\u001b[0m\u001b[1;33m\u001b[0m\u001b[0m\n\u001b[0;32m      3\u001b[0m     \u001b[0mPeriod\u001b[0m\u001b[1;33m,\u001b[0m\u001b[1;33m\u001b[0m\u001b[1;33m\u001b[0m\u001b[0m\n\u001b[0;32m      4\u001b[0m     \u001b[0mTimedelta\u001b[0m\u001b[1;33m,\u001b[0m\u001b[1;33m\u001b[0m\u001b[1;33m\u001b[0m\u001b[0m\n\u001b[0;32m      5\u001b[0m     \u001b[0mTimestamp\u001b[0m\u001b[1;33m,\u001b[0m\u001b[1;33m\u001b[0m\u001b[1;33m\u001b[0m\u001b[0m\n",
      "\u001b[1;32m~\\anaconda3\\lib\\site-packages\\pandas\\_libs\\__init__.py\u001b[0m in \u001b[0;36m<module>\u001b[1;34m\u001b[0m\n\u001b[0;32m     16\u001b[0m \u001b[1;32mimport\u001b[0m \u001b[0mpandas\u001b[0m\u001b[1;33m.\u001b[0m\u001b[0m_libs\u001b[0m\u001b[1;33m.\u001b[0m\u001b[0mpandas_parser\u001b[0m  \u001b[1;31m# isort: skip # type: ignore[reportUnusedImport]\u001b[0m\u001b[1;33m\u001b[0m\u001b[1;33m\u001b[0m\u001b[0m\n\u001b[0;32m     17\u001b[0m \u001b[1;32mimport\u001b[0m \u001b[0mpandas\u001b[0m\u001b[1;33m.\u001b[0m\u001b[0m_libs\u001b[0m\u001b[1;33m.\u001b[0m\u001b[0mpandas_datetime\u001b[0m  \u001b[1;31m# noqa: F401 # isort: skip # type: ignore[reportUnusedImport]\u001b[0m\u001b[1;33m\u001b[0m\u001b[1;33m\u001b[0m\u001b[0m\n\u001b[1;32m---> 18\u001b[1;33m \u001b[1;32mfrom\u001b[0m \u001b[0mpandas\u001b[0m\u001b[1;33m.\u001b[0m\u001b[0m_libs\u001b[0m\u001b[1;33m.\u001b[0m\u001b[0minterval\u001b[0m \u001b[1;32mimport\u001b[0m \u001b[0mInterval\u001b[0m\u001b[1;33m\u001b[0m\u001b[1;33m\u001b[0m\u001b[0m\n\u001b[0m\u001b[0;32m     19\u001b[0m from pandas._libs.tslibs import (\n\u001b[0;32m     20\u001b[0m     \u001b[0mNaT\u001b[0m\u001b[1;33m,\u001b[0m\u001b[1;33m\u001b[0m\u001b[1;33m\u001b[0m\u001b[0m\n",
      "\u001b[1;32mpandas\\_libs\\interval.pyx\u001b[0m in \u001b[0;36minit pandas._libs.interval\u001b[1;34m()\u001b[0m\n",
      "\u001b[1;31mValueError\u001b[0m: numpy.dtype size changed, may indicate binary incompatibility. Expected 96 from C header, got 88 from PyObject"
     ]
    }
   ],
   "source": [
    "import zipfile\n",
    "import os\n",
    "import pandas as pd\n",
    "\n",
    "# Load Data set\n",
    "zip_path = 'C:/Users/USER/OneDrive/Desktop/Data science/Data Analyst Applications/archive (1).zip'\n",
    "extract_path = 'ecommerce_data'\n",
    "\n",
    "# Unzip the file\n",
    "with zipfile.ZipFile(zip_path, 'r') as zip_ref:\n",
    "    zip_ref.extractall(extract_path)\n",
    "\n",
    "# List files\n",
    "os.listdir(extract_path)"
   ]
  },
  {
   "cell_type": "code",
   "execution_count": null,
   "id": "2bf981a6",
   "metadata": {},
   "outputs": [],
   "source": []
  }
 ],
 "metadata": {
  "kernelspec": {
   "display_name": "Python 3 (ipykernel)",
   "language": "python",
   "name": "python3"
  },
  "language_info": {
   "codemirror_mode": {
    "name": "ipython",
    "version": 3
   },
   "file_extension": ".py",
   "mimetype": "text/x-python",
   "name": "python",
   "nbconvert_exporter": "python",
   "pygments_lexer": "ipython3",
   "version": "3.9.13"
  }
 },
 "nbformat": 4,
 "nbformat_minor": 5
}
